Workbook

Sheet Ελλάδα
A1: Ημερομηνία | B1: Ώρα έναρξης | C1: Ώρα ελέγχου | D1: Ώρα κατάσβεσης | E1: Πυρκαγιά / Περιοχή | F1: Περιφέρεια | G1: Νομός | H1: Δήμος | I1: Πυροσβέστες | J1: Οχήματα | K1: Αεροσκάφη | L1: Ελικόπτερα | M1: Επίγειες ομάδες | N1: Δήμοι/Περιφέρειες | O1: Εθελοντές | P1: Καμμένη έκταση (ha) | Q1: Κίνδυνος (1-5) | R1: Κατηγορία κινδύνου | S1: Κατάσταση | T1: Αιτία | U1: 112 (Εκκ./Προειδ.) | V1: Πηγές | W1: Σημειώσεις | X1: Ενημερώθηκε | Y1: _μήνας | Z1: _έκταση0 | AA1: _επιλ
A2: 46288 | B2: 11:30 | E2: Δίστρατο Κόνιτσας | F2: Ήπειρος | G2: Ιωαννίνων | H2: Κόνιτσα | I2: 10 | J2: 1 | K2: 0 | L2: 1 | M2: 1 ομάδα πεζοπόρου (5ης ΕΜΟΔΕ) | P2: <10 ha | Q2: 1 | R2: ΧΑΜΗΛΗ | S2: σε εξέλιξη | T2: κεραυνός | V2: https://www.in.gr/2026/09/23/greece/fotia-sto-distrato-konitsas-sikothike-elikoptero/ ; https://www.newsbeast.gr/greece/arthro/13376247/fotia-se-dasiki-ektasi-sto-distrato-konitsas ; https://www.eleftherostypos.gr/ellada/fotia-tora-stin-distrato-konitsas-epicheirei-ena-elikoptero ; https://www.documentonews.gr/article/fotia-tora-stin-konitsa-sti-machi-tis-katasvesis-kai-elikoptero/ | W2: Ξεχωριστό περιστατικό από τη φωτιά Βασιλίτσας (22/9) — διαφορετική τοποθεσία, διαφορετική ημέρα. Δύσβατο/δυσπρόσιτο σημείο, αδυναμία πρόσβασης οχημάτων. Μαρτυρίες κατοίκων: κεραυνός (ασταθής ατμόσφαιρα Πίνδου). | ⚠ pyr_postfix 2026-09-23: έκταση μη δημοσιευμένη· η κλίμακα απόκρισης (≤25 πυροσβέστες, ≤4 εναέρια, ≤12 οχήματα) αποκλείει μεγάλο συμβάν. Το «<10 ha» είναι ΣΥΜΠΕΡΑΣΜΑ, όχι μέτρηση, και δεν προσμετράται στα αθροίσματα. | X2: 2026-09-23 | Y2: 9 | Z2: 0 | AA2: =IF('Στατιστικά'!$C$6,1,IFERROR(INDEX('Στατιστικά'!$C$10:$C$83,MATCH(G2,'Στατιστικά'!$B$10:$B$83,0))*1,0)) -> 1
A3: 46287 | B3: 12:50 | E3: Μαυροβούνι Κορωπίου (Υμηττός) | F3: Αττικής | G3: Αττικής | H3: Κορωπί | J3: 4 | K3: 0 | L3: 0 | Q3: 2 | R3: ΜΕΣΗ | T3: κεραυνός | V3: https://www.mononews.gr/society/fotia-apo-keravno-sto-mavrovouni-koropiou-stous-propodes-tou-ymittou ; https://pressing.gr/ellada/keravnoi-prokaloun-pyrkagies-apo-tin-kerkyra-os-ton-ymitto-synagermos-se-kanoni-kai-koropi/ ; https://www.newsbomb.gr/ellada/story/1765140/keraynoi-prokaloyn-pyrkagies-apo-tin-kerkyra-eos-ton-ymitto-synagermos-se-kanoni-kai-koropi ; https://voicenews.gr/pyrkagia-se-dasiki-ektasi-ston-ymitto-meta-apo-ptosi-keravnou/ ; https://www.naftemporiki.gr/society/2164966/fotia-tora-apo-kerayno-sto-mayrovoyni-koropioy-stoys-propodes-toy-ymittoy/ ; https://www.flash.gr/ymittos-fotia-se-dasiki-ektasi-meta-apo-ptosi-keraynoy-1082417 ; https://www.eleftherostypos.gr/ellada/fotia-tora-stous-propodes-tou-ymittou-keravnos-chtypise-sto-mavrovouni-koropiou ; https://www.documentonews.gr/article/fotia-tora-sto-koropi-apo-keravno-se-dasiki-ektasi-sti-thesi-mavrovouni/amp/ | W3: Πτώση κεραυνού λίγο πριν 13:00· πρόποδες Υμηττού, δύσβατη έκταση· βροχή κατά την επιχείρηση· μέρος κύματος κεραυνοπτώσεων 22/9 από Κόνιτσα έως Υμηττό | Δασική έκταση στους πρόποδες Υμηττού. Πτώση κεραυνού εν μέσω καταιγίδας. Δύσβατο σημείο, βροχή. Ισχυρές επίγειες δυνάμεις Πυροσβεστικής (αριθμός δεν αναφέρεται). | X3: 2026-09-23 | Y3: 9 | Z3: 0 | AA3: =IF('Στατιστικά'!$C$6,1,IFERROR(INDEX('Στατιστικά'!$C$10:$C$83,MATCH(G3,'Στατιστικά'!$B$10:$B$83,0))*1,0)) -> 1
A4: 46287 | B4: 00:30 | E4: Γυαλός Αθανίου | F4: Ιόνιοι Νήσοι | G4: Λευκάδας | H4: Λευκάδα | K4: 0 | L4: 0 | Q4: 2 | R4: ΜΕΣΗ | V4: https://www.tanea.gr/2026/09/23/greece/agonia-sti-leykada-metamesonyktia-pyrkagia-se-dasiki-perioxi-ston-gyalo/ ; https://www.inewsgr.com/27/agonia-sti-lefkada--metamesonyktia-pyrkagia-se-dasiki-periochi-ston-gyalo.htm ; https://athlosnews.gr/1056105/agonia-sti-lefkada-pyrkagia-meta-ta-mesanychta-se-dasiki-periochi-ston-gyalo/ | W4: Μεταμεσονύχτια πυρκαγιά (λίγο μετά τα μεσάνυχτα Τρίτης 22/9). Ισχυροί άνεμοι. Πρώτες δυνάμεις από Κονταράινα ~00:30. Δεν εντοπίστηκαν στοιχεία 112 ή τελική κατάσταση. | X4: 2026-09-23 | Y4: 9 | Z4: 0 | AA4: =IF('Στατιστικά'!$C$6,1,IFERROR(INDEX('Στατιστικά'!$C$10:$C$83,MATCH(G4,'Στατιστικά'!$B$10:$B$83,0))*1,0)) -> 1
A5: 46287 | B5: 00:30 | E5: Γυαλός Λευκάδας (Αθάνιο) | F5: Ιονίων Νήσων | G5: Λευκάδος | H5: Λευκάδα | Q5: 2 | R5: ΜΕΣΗ | V5: https://www.tanea.gr/2026/09/23/greece/agonia-sti-leykada-metamesonyktia-pyrkagia-se-dasiki-perioxi-ston-gyalo/ | W5: Εκδηλώθηκε λίγο μετά τα μεσάνυχτα 21→22/9· δασική περιοχή πάνω από Γυαλό περιοχής Αθανίου· κάτοικοι επιχείρησαν αρχικά με κλαδιά· πυρ/στές από Κοντάραινα και πόλη Λευκάδας· δυνατοί άνεμοι στην περιοχή | ⚠ pyr_postfix 2026-09-23: διπλοεγγραφή του ίδιου συμβάντος· η έκταση δεν προσμετράται (_έκταση0=0). Φέρουσα εγγραφή: γραμμή 4. | X5: 2026-09-23 | Y5: 9 | Z5: 0 | AA5: =IF('Στατιστικά'!$C$6,1,IFERROR(INDEX('Στατιστικά'!$C$10:$C$83,MATCH(G5,'Στατιστικά'!$B$10:$B$83,0))*1,0)) -> 1
A6: 46287 | E6: Βασιλίτσα Κόνιτσας | F6: Ηπείρου | G6: Ιωαννίνων | H6: Κόνιτσα | I6: 10 | J6: 1 | K6: 1 | L6: 1 | M6: 1 ομάδα πεζοπόρων 5ης ΕΜΟΔΕ | P6: <10 ha | Q6: 2 | R6: ΜΕΣΗ | S6: σε εξέλιξη | T6: κεραυνός | V6: https://www.cnn.gr/ellada/story/553523/fotia-se-dasiki-perioxi-stin-vasilitsa-konitsas-sikothike-aeroskafos ; https://www.protothema.gr/greece/article/1882783/fotia-stin-vasilitsa-konitsas-sikothike-1-elikoptero/ ; https://www.firefightingreece.gr/2026/09/22/pyrkagia-se-dasiki-ektasi-sti-vasilitsa-konitsas-epicheiroun-10-pyrosvestes-kai-1-elikoptero/ ; https://www.tanea.gr/2026/09/22/greece/fotia-sti-vasilitsa-konitsas-sikothike-ena-elikoptero/ ; https://voicenews.gr/fotia-se-dysvati-dasiki-ektasi-sti-vasilitsa-konitsas-apo-ptosi-keravnou/ ; https://thepressproject.gr/fotia-xespase-se-dasiki-ektasi-sti-vasilitsa-konitsas/ ; https://www.madata.gr/epikairotita/social/981522-fotia-sti-vasilitsa-konitsas-se-exelixi-i-epicheirisi-katasvesis-me-epigeies-kai-enaeries-dynameis.html ; https://pressing.gr/ellada/fotia-se-dasiki-ektasi-sti-vasilitsa-konitsas/ | W6: Δύσβατη-απρόσιτη έκταση· αδύνατη πρόσβαση πυροσβεστικών οχημάτων· αιτία πτώση κεραυνού (στο πλαίσιο καταιγίδας 22/9)· ξεχωριστή φωτιά από Τραπεζίτσα αν και ίδιος Δήμος | Δύσβατο/δυσπρόσιτο σημείο. Αέρια μέσα: tanea αναφέρει ελικόπτερο, CNN.gr αναφέρει αεροσκάφος — πιθανώς το ίδιο μέσο, ασαφής ορολογία. Αίτιο κεραυνός (συμφραζόμενα ίδιας ημέρας με κεραυνική δραστηριότητα). | ⚠ pyr_postfix 2026-09-23: έκταση μη δημοσιευμένη· η κλίμακα απόκρισης (≤25 πυροσβέστες, ≤4 εναέρια, ≤12 οχήματα) αποκλείει μεγάλο συμβάν. Το «<10 ha» είναι ΣΥΜΠΕΡΑΣΜΑ, όχι μέτρηση, και δεν προσμετράται στα αθροίσματα. | X6: 2026-09-23 | Y6: 9 | Z6: 0 | AA6: =IF('Στατιστικά'!$C$6,1,IFERROR(INDEX('Στατιστικά'!$C$10:$C$83,MATCH(G6,'Στατιστικά'!$B$10:$B$83,0))*1,0)) -> 1
A7: 46287 | E7: Μαυροβούνι-Λακίζα | F7: Αττική | G7: Αττικής | H7: Κρωπίας | Q7: 2 | R7: ΜΕΣΗ | S7: σε εξέλιξη | T7: κεραυνός | V7: https://www.paraskhnio.gr/2026/09/22/koropi-fotia-ston-ymitto-meta-apo-ptosi-keravnou/ ; https://www.irafina.gr/koropi-fotia-apo-keravno-sto-mavrovouni/ ; https://www.patrisnews.com/keraynoi-prokaloyn-pyrkagies-apo-tin-kerkyra-os-ton-ymitto-synagermos-se-kanoni-kai-koropi/ ; https://www.newsbomb.gr/ellada/story/1765140/keravnoi-prokaloyn-pyrkagies-apo-tin-kerkyra-eos-ton-ymitto-synagermos-se-kanoni-kai-koropi | W7: Δασική έκταση στις πλαγιές Υμηττού. Δύσβατο έδαφος + βροχή δυσχέραναν επιχειρήσεις. Μέρος ευρύτερης κεραυνικής δραστηριότητας 22/09 (>25.000 κεραυνοί πανελλαδικά). Αμιγώς δασική/φυσική περιοχή. | X7: 2026-09-23 | Y7: 9 | Z7: 0 | AA7: =IF('Στατιστικά'!$C$6,1,IFERROR(INDEX('Στατιστικά'!$C$10:$C$83,MATCH(G7,'Στατιστικά'!$B$10:$B$83,0))*1,0)) -> 1
A8: 46286 | B8: 19:00 | E8: Κοτσύλια Υλίκης | F8: Στερεά Ελλάδα | G8: Βοιωτίας | I8: 26 | J8: 9 | K8: 0 | L8: 1 | M8: 1 ομάδα πεζοπόρου (4ης ΕΜΟΔΕ) | Q8: 2 | R8: ΜΕΣΗ | S8: υπό μερικό έλεγχο | T8: ύποπτο | V8: https://www.kanaliena.gr/voiotia-ypo-meriko-elegcho-i-fotia-konta-sti-limni-yliki/ ; https://www.policenet.gr/article/pyrkagia-se-agrotodasiki-ektasi-konta-sti-limni-yliki ; https://www.skaikritis.gr/fotia-sti-voiotia-synagermos-konta-sti-limni-yliki-sikothike-elikoptero/ | W8: Αγροτοδασική έκταση κοντά στη λίμνη Υλίκη. Αρσονιστική ανάκριση από ομάδα Φθιώτιδας. | X8: 2026-09-23 | Y8: 9 | Z8: 0 | AA8: =IF('Στατιστικά'!$C$6,1,IFERROR(INDEX('Στατιστικά'!$C$10:$C$83,MATCH(G8,'Στατιστικά'!$B$10:$B$83,0))*1,0)) -> 1
A9: 46286 | B9: 14:45 | E9: Στρυμονικό Σερρών | F9: Κεντρικής Μακεδονίας | G9: Σερρών | H9: Ηράκλεια | I9: 52 | J9: 17 | K9: 2 | L9: 2 | M9: 2 ομάδες πεζοπόρων 2ης ΕΜΟΔΕ | N9: υδροφόρες Δήμου Ηράκλειας | P9: 20 | Q9: 2 | R9: ΜΕΣΗ | S9: κατασβέστηκε | T9: υπό έρευνα (πιθανός εμπρησμός) | V9: https://www.cnn.gr/ellada/story/553348/dasiki-pyrkagia-sto-strymoniko-serron-epixeiroyn-dyo-elikoptera ; https://www.newsbomb.gr/ellada/story/1764899/fotia-se-dasiki-ektasi-sto-strymoniko-serron-epixeiroyn-dyo-elikoptera ; https://www.naftemporiki.gr/society/2164526/serres-fotia-kai-pali-sto-strymoniko/ ; https://debater.gr/ellada/fotia-sto-strymoniko-serron-kaiei-dasiki-ektasi/ ; https://voicenews.gr/pyrkagia-se-dasiki-ektasi-sto-strymoniko-serron/ ; https://www.thestival.gr/eidiseis/astynomika/choris-energo-metopo-i-fotia-se-dasiki-e-3/ ; https://www.newsbomb.gr/ellada/story/1764552/serres-mia-syllipsi-gia-ti-fotia-sto-strymoniko ; https://www.dimocracy.gr/epikairotita/fotia-sto-strymoniko-serron-synelifthi-odigos-vytioforou/ | W9: Χωρίς ενεργό μέτωπο ~17:18· δεύτερη φωτιά στο ίδιο σημείο σε λίγες ημέρες· παρακολούθηση ΕΣΚΕΔΙΚ με drones θερμικής/οπτικής απεικόνισης· έρευνα Ανακριτικού Κλιμακίου Εμπρησμού Σερρών | X9: 2026-09-23 | Y9: 9 | Z9: 20 | AA9: =IF('Στατιστικά'!$C$6,1,IFERROR(INDEX('Στατιστικά'!$C$10:$C$83,MATCH(G9,'Στατιστικά'!$B$10:$B$83,0))*1,0)) -> 1
A10: 46285 | B10: 18:00 | E10: Λουτράκι Αλμωπίας | F10: Κεντρική Μακεδονία | G10: Πέλλης | H10: Αλμωπίας | I10: 16 | J10: 2 | L10: 3 | M10: 2 ορειβατικές ομάδες 2ης ΕΜΟΔΕ | N10: Δήμος Αλμωπίας (υδροφόρες) | P10: <10 ha | Q10: 2 | R10: ΜΕΣΗ | S10: σε εξέλιξη | T10: κεραυνοί | V10: https://www.tanea.gr/2026/09/20/greece/pella-pyrkagia-se-dysprositi-dasiki-ektasi-epixeiroun-3-elikoptera/ ; https://www.newsit.gr/ellada/fotia-stin-pella-stin-perioxi-loutraki-kinitopoiithikan-16-pyrosvestes/4779155/ ; https://www.newsbomb.gr/ellada/story/1764687/pyrkagia-stin-pella-kaiei-se-dysprositi-dasiki-perioxi-epixeiroyn-kai-3-elikoptera | W10: Δυσπρόσιτη/δύσβατη δασική περιοχή — αδύνατη πρόσβαση πυροσβεστικών οχημάτων. Αποκλειστικά ελικόπτερα για αεροπυρόσβεση. Αιτία: έντονη κεραυνική δραστηριότητα 20/09. | ⚠ pyr_postfix 2026-09-23: έκταση μη δημοσιευμένη· η κλίμακα απόκρισης (≤25 πυροσβέστες, ≤4 εναέρια, ≤12 οχήματα) αποκλείει μεγάλο συμβάν. Το «<10 ha» είναι ΣΥΜΠΕΡΑΣΜΑ, όχι μέτρηση, και δεν προσμετράται στα αθροίσματα. | X10: 2026-09-23 | Y10: 9 | Z10: 0 | AA10: =IF('Στατιστικά'!$C$6,1,IFERROR(INDEX('Στατιστικά'!$C$10:$C$83,MATCH(G10,'Στατιστικά'!$B$10:$B$83,0))*1,0)) -> 1
A11: 46285 | B11: 14:30 | E11: Χώνος Σητείας | F11: Κρήτη | G11: Λασιθίου | H11: Σητεία | I11: 105 | J11: 35 | K11: 0 | L11: 2 | M11: 5 ομάδες πεζοπόρου (3ης & 19ης ΕΜΟΔΕ) | N11: Δήμος Σητείας (βυτιοφόρα) | Q11: 3 | R11: ΥΨΗΛΗ | S11: οριοθετήθηκε | U11: 20/9 ~17:00 εκκένωση Καρυδίου → Ζάκρος· ~20:27 ετοιμότητα Ζάκρος/Κλισίδι/Αδράβαστοι/Αζωκέραμο/Κελλαριά· ~23:30 εκκένωση Κελλαριά/Αδράβαστη/Αζώκεραμος → Παλαίκαστρο· ~23:35 εκκένωση Ζάκρος → Ξερόκαμπο | V11: https://www.liberal.gr/ellada/fotia-ston-hono-lasithioy-112-gia-etoimotita-se-polles-periohes-kai-ekkenosi-sto-karydi ; https://www.larissanet.gr/2026/09/20/fotia-sto-lasithi-stin-periochi-chonos-neo-112-gia-etoimotita-se-pente-choria-kai-gia-ekkenosi-sto-karydi-vinteo/ ; https://www.newsit.gr/ellada/fotia-sto-lasithi-stin-perioxi-xonos-nea-112-gia-ekkenosi-pros-kserokampo-kai-palaikastro-vinteo/4779200/ ; https://www.ertnews.gr/perifereiakoi-stathmoi/mainetai-i-fotia-sto-lasithi-neo-112-gia-ekkenosi-pros-kserokampo/ ; https://www.in.gr/2026/09/21/greece/kriti-xoris-energo-metopo-i-fotia-ston-xono-lasithiou/ ; https://www.madata.gr/epikairotita/social/981031-fotia-sti-siteia-minyma-toy-112-gia-ekkenosi-toy-karydioy-pros-zakro.html ; https://www.tanea.gr/2026/09/20/greece/fotia-sto-lasithi-112-gia-ekkenosi-tis-perioxis-karydi-sti-maxi-kai-enaeria-mesa-video ; https://www.iefimerida.gr/ellada/se-exelixi-i-megali-fotia-sti-siteia-neo-minyma-apo-112-gia-ekkenosi ; https://www.in.gr/2026/09/20/greece/olonyxtia-maxi-me-ti-fotia-sti-siteia-neo-minyma-apo-to-112-gia-ekkenosi/ ; https://www.alt.gr/lasithi-choris-energo-metopo-i-pyrkagia/ ; https://www.rizospastis.gr/story.do?id=13419120 | W11: Ολονύχτια μάχη. 4 σήματα 112 για εκκένωση/ετοιμότητα 6 οικισμών. Πρωί 21/9 χωρίς ενεργό μέτωπο. Ενισχύθηκαν δυνάμεις διαρκώς κατά τη νύχτα (αρχική κινητοποίηση: 46 πυροσβέστες, 15 οχήματα, 3 ελικόπτερα). | X11: 2026-09-23 | Y11: 9 | Z11: 0 | AA11: =IF('Στατιστικά'!$C$6,1,IFERROR(INDEX('Στατιστικά'!$C$10:$C$83,MATCH(G11,'Στατιστικά'!$B$10:$B$83,0))*1,0)) -> 1
A12: 46282 | B12: 13:20 | E12: Παλαμάς | F12: Θεσσαλία | G12: Καρδίτσης | H12: Παλαμά | I12: 25 | J12: 7 | K12: 4 | L12: 1 | M12: 1 ορειβατική ομάδα 10ης ΕΜΟΔΕ | Q12: 2 | R12: ΜΕΣΗ | V12: https://www.skai.gr/news/greece/pyrkagia-se-xamili-vlastisi-ston-palama-karditsas-epixeiroun-4-enaeria ; https://www.efsyn.gr/ellada/1469093/fotia-ston-palama-karditsas-epiheiroyn-tessera-aeroskafi/ ; https://www.lamiareport.gr/topika/topikanea/item/pyrkagia-stin-karditsa-epixeiroun-enaeria-mesa-ston-dimo-palama/ | W12: Χαμηλή βλάστηση (όχι αμιγώς δασική). Σημαντική αεροπυρόσβεση παρά τον χαμηλό κίνδυνο. Πυροσβεστική ενημερώθηκε ~13:20. | X12: 2026-09-23 | Y12: 9 | Z12: 0 | AA12: =IF('Στατιστικά'!$C$6,1,IFERROR(INDEX('Στατιστικά'!$C$10:$C$83,MATCH(G12,'Στατιστικά'!$B$10:$B$83,0))*1,0)) -> 1
A13: 46281 | B13: 10:45 | E13: Παραδείσι | F13: Στερεά Ελλάδα | G13: Εύβοιας | H13: Καρύστου | I13: 36 | J13: 9 | K13: 2 | L13: 2 | M13: 1 ορειβατική ομάδα 20ης ΕΜΟΔΕ | N13: Δήμος Καρύστου (υδροφόρες) | Q13: 3 | R13: ΥΨΗΛΗ | S13: οριοθετήθηκε | T13: υπό διερεύνηση | U13: 112: ετοιμότητα κατοίκων Παραδείσι — ακολουθήστε οδηγίες αρχών (16/09 ~10:45) | V13: https://www.ertnews.gr/eidiseis/eyvoia-xoris-energo-metopo-i-pyrkagia-se-dasiki-ektasi-stin-perioxi-paradeisi-ixise-to-112/ ; https://www.emakedonia.gr/synagermos-stin-eyvoia-kaigetai-dasiki-ektasi-sto-paradeisi-ischyri-paroysia-enaerion-meson ; https://ecozen.gr/2026/09/pyrkagia-se-dasiki-ektasi-sto-paradeisi-evvoias-epicheiroun-epigeia-kai-enaeria-mesa/ ; https://www.newsbeast.gr/greece/arthro/13359934/fotia-tora-sto-paradeisi-evvoias-minyma-tou-112 | W13: Χωρίς ενεργό μέτωπο (ertnews). Κατηγορία κινδύνου 3 (ertnews). Χάρτης 16/09 επισημαίνει αυξημένο κίνδυνο σε περιοχές με πτώση κεραυνών. | X13: 2026-09-23 | Y13: 9 | Z13: 0 | AA13: =IF('Στατιστικά'!$C$6,1,IFERROR(INDEX('Στατιστικά'!$C$10:$C$83,MATCH(G13,'Στατιστικά'!$B$10:$B$83,0))*1,0)) -> 1
A14: 46281 | E14: Ξύγκια | F14: Ιόνιοι Νήσοι | G14: Ζακύνθου | H14: Ζακύνθου | I14: 31 | J14: 10 | K14: 6 | M14: 1 ορειβατική ομάδα 17ης ΕΜΟΔΕ | N14: τοπικές υδροφόρες | O14: εθελοντές | Q14: 2 | R14: ΜΕΣΗ | S14: υπό έλεγχο | V14: https://www.ertnews.gr/perifereiakoi-stathmoi/zakinthos/zakynthos-pyrkagia-se-dasiki-ektasi-sta-ksygkia/ | W14: Απόγευμα 16/09 (ενημέρωση 17:17). Δασική έκταση — δεν απειλήθηκαν κατοικημένες περιοχές. 6 αεροσκάφη (fixed-wing). | X14: 2026-09-23 | Y14: 9 | Z14: 0 | AA14: =IF('Στατιστικά'!$C$6,1,IFERROR(INDEX('Στατιστικά'!$C$10:$C$83,MATCH(G14,'Στατιστικά'!$B$10:$B$83,0))*1,0)) -> 1
A15: 46279 | E15: Ανατολή | F15: Θεσσαλία | G15: Λαρίσης | K15: 5 | M15: επίγειες δυνάμεις | Q15: 2 | R15: ΜΕΣΗ | V15: https://www.ekathimerini.com/news/1315214/wildfires-hit-forests-in-northern-greece-despite-lower-risk/ | W15: 5 αεροσκάφη ρίψης νερού. Χωρίς αναφορές ζημιών. Ώρα info: 16:16 EEST (ekathimerini). | X15: 2026-09-23 | Y15: 9 | Z15: 0 | AA15: =IF('Στατιστικά'!$C$6,1,IFERROR(INDEX('Στατιστικά'!$C$10:$C$83,MATCH(G15,'Στατιστικά'!$B$10:$B$83,0))*1,0)) -> 1
A16: 46279 | E16: Ελάνη | F16: Κεντρική Μακεδονία | G16: Χαλκιδικής | K16: 7 | M16: επίγειες δυνάμεις | Q16: 2 | R16: ΜΕΣΗ | V16: https://www.ekathimerini.com/news/1315214/wildfires-hit-forests-in-northern-greece-despite-lower-risk/ | W16: 7 εναέρια μέσα (αεροσκάφη+ελικόπτερα, διάκριση άγνωστη). Χωρίς αναφορές ζημιών σε ιδιοκτησίες ή τραυματισμών. Πυρκαγιά παρά τον ηπιότερο κίνδυνο της ημέρας (ekathimerini). | X16: 2026-09-23 | Y16: 9 | Z16: 0 | AA16: =IF('Στατιστικά'!$C$6,1,IFERROR(INDEX('Στατιστικά'!$C$10:$C$83,MATCH(G16,'Στατιστικά'!$B$10:$B$83,0))*1,0)) -> 1
A17: 46277 | B17: 13:30 | E17: Στρουμπούλα-Λευκά | F17: Νότιο Αιγαίο | G17: Κυκλάδων | H17: Πάρου | I17: 17 | J17: 5 | K17: 4 | L17: 2 | N17: Δήμος Πάρου (υδροφόρες, μηχάνημα έργου) | O17: ΔΕΥΑΠ | Q17: 3 | R17: ΥΨΗΛΗ | S17: υπό έλεγχο | T17: ανάφλεξη τετράτροχου οχήματος | V17: https://www.cnn.gr/ellada/story/552104/oriothetithike-i-fotia-stin-paro-se-epifylaki-gia-anazopyroseis | W17: 10 πυροσβέστες από Πάρο + 7 από Σύρο. Υπό πλήρη έλεγχο — επιφυλακή για αναζωπυρώσεις. Χαμηλή βλάστηση γύρω από τετράτροχο που τυλίχθηκε φλόγες. | X17: 2026-09-23 | Y17: 9 | Z17: 0 | AA17: =IF('Στατιστικά'!$C$6,1,IFERROR(INDEX('Στατιστικά'!$C$10:$C$83,MATCH(G17,'Στατιστικά'!$B$10:$B$83,0))*1,0)) -> 1
A18: 46273 | B18: 07:00 | E18: Ευκαρπία Θεσσαλονίκης | F18: Κεντρική Μακεδονία | G18: Θεσσαλονίκης | H18: Παύλος Μελάς | I18: 10 | J18: 4 | P18: <10 ha | Q18: 3 | R18: ΥΨΗΛΗ | S18: οριοθετήθηκε | V18: https://www.ertnews.gr/video/thessaloniki-oriothetithike-i-fotia-pou-ksespase-stin-eykarpia/ ; https://www.naftemporiki.gr/society/1971170/thessaloniki-oriothetithike-i-pyrkagia-stin-eykarpia-se-exelixi-fotia-se-chorta-sti-thermi/ ; https://www.emakedonia.gr/thessaloniki-pyrkagia-se-xira-chorta-konta-stin-eykarpia-sto-simeio-i-pyrosvestiki ; https://cretaone.gr/thessaloniki-synagermos-gia-fotia-se-xera-chorta/ | W18: Φωτιά σε ξερά χόρτα κοντά σε ΤΙΤΑΝ. Γρήγορη οριοθέτηση. Υλικές ζημιές σε όχημα. 112 δεν επιβεβαιώθηκε για αυτό το συγκεκριμένο συμβάν 08-09. | ⚠ pyr_postfix 2026-09-23: έκταση μη δημοσιευμένη· η κλίμακα απόκρισης (≤25 πυροσβέστες, ≤4 εναέρια, ≤12 οχήματα) αποκλείει μεγάλο συμβάν. Το «<10 ha» είναι ΣΥΜΠΕΡΑΣΜΑ, όχι μέτρηση, και δεν προσμετράται στα αθροίσματα. | X18: 2026-09-08 | Y18: 9 | Z18: 0 | AA18: =IF('Στατιστικά'!$C$6,1,IFERROR(INDEX('Στατιστικά'!$C$10:$C$83,MATCH(G18,'Στατιστικά'!$B$10:$B$83,0))*1,0)) -> 1
A19: 46273 | E19: Πανασός | F19: Κρήτη | G19: Ηρακλείου | I19: 35 | J19: 10 | Q19: 4 | R19: ΠΟΛΥ ΥΨΗΛΗ | S19: υπό έλεγχο | V19: https://www.newsbomb.gr/ellada/story/1761801/foties-olonyxtia-i-maxi-ton-pyrosveston-sta-pyrina-metopa-red-code-simera-se-polles-perioxes | W19: Εκδηλώθηκε τη νύχτα 7/8 Σεπ. Τέθηκε γρήγορα υπό έλεγχο. | X19: 2026-09-08 | Y19: 9 | Z19: 0 | AA19: =IF('Στατιστικά'!$C$6,1,IFERROR(INDEX('Στατιστικά'!$C$10:$C$83,MATCH(G19,'Στατιστικά'!$B$10:$B$83,0))*1,0)) -> 1
A20: 46273 | E20: Πλάτη Τριφυλίας | F20: Πελοπόννησος | G20: Μεσσηνίας | H20: Τριφυλίας | I20: 16 | J20: 8 | P20: 1 | Q20: 3 | R20: ΥΨΗΛΗ | S20: οριοθετήθηκε | V20: https://www.ertnews.gr/perifereiakoi-stathmoi/kalamata/messinia-ypo-elegxo-pyrkagia-stin-plati-trifylias-kaikan-peripou-10-stremmata/ ; https://www.enikos.gr/society/fotia-sti-messinia-oriothetithike-amesa-apo-tin-pyrosvestiki/2640596/ | W20: Αγροτοδασική έκταση. 10 στρέμματα = 1 ha. Γρήγορη επέμβαση απέτρεψε μεγαλύτερη εξάπλωση. | X20: 2026-09-08 | Y20: 9 | Z20: 1 | AA20: =IF('Στατιστικά'!$C$6,1,IFERROR(INDEX('Στατιστικά'!$C$10:$C$83,MATCH(G20,'Στατιστικά'!$B$10:$B$83,0))*1,0)) -> 1
A21: 46273 | E21: Πλατύ Μεσσηνίας | F21: Πελοπόννησος | G21: Μεσσηνίας | H21: Μεσσήνη | I21: 16 | J21: 8 | P21: <10 ha | Q21: 4 | R21: ΠΟΛΥ ΥΨΗΛΗ | S21: σε εξέλιξη | V21: https://www.protothema.gr/greece/article/1875412/fotia-se-agrotodasiki-ektasi-sto-plati-messinias/ ; https://www.cnn.gr/ellada/story/551323/fotia-se-agrotodasiki-ektasi-sto-plati-messinias ; https://www.documentonews.gr/article/fotia-tora-sto-plati-messinias/ ; https://www.athensvoice.gr/epikairotita/ellada/984156/fotia-tora-sto-plati-messinias/ | W21: Αγροτοδασική έκταση. Πρωινή εκδήλωση. Κατηγορία κινδύνου 4 (ΠΟΛΥ ΥΨΗΛΗ) για Πελοπόννησο / Μεσσηνία 08-09. | ⚠ pyr_postfix 2026-09-23: έκταση μη δημοσιευμένη· η κλίμακα απόκρισης (≤25 πυροσβέστες, ≤4 εναέρια, ≤12 οχήματα) αποκλείει μεγάλο συμβάν. Το «<10 ha» είναι ΣΥΜΠΕΡΑΣΜΑ, όχι μέτρηση, και δεν προσμετράται στα αθροίσματα. | X21: 2026-09-08 | Y21: 9 | Z21: 0 | AA21: =IF('Στατιστικά'!$C$6,1,IFERROR(INDEX('Στατιστικά'!$C$10:$C$83,MATCH(G21,'Στατιστικά'!$B$10:$B$83,0))*1,0)) -> 1
A22: 46272 | B22: 21:15 | E22: Ασπροκκλησιά Καλαμπάκας | F22: Θεσσαλία | G22: Τρικάλων | H22: Καλαμπάκα | I22: 20 | J22: 7 | M22: 1 πεζοπόρος ομάδα 10ης ΕΜΟΔΕ | N22: υδροφόρες Δήμου Καλαμπάκας | P22: <10 ha | Q22: 3 | R22: ΥΨΗΛΗ | S22: σε εξέλιξη | V22: https://www.karditsalive.net/eidiseis/thessalia/trikala/%CE%B4%CE%B1%CF%83%CE%B9%CE%BA%CE%AE-%CF%80%CF%85%CF%81%CE%BA%CE%B1%CE%B3%CE%B9%CE%AC-%CF%83%CF%84%CE%B7%CE%BD-%CE%B1%CF%83%CF%80%CF%81%CE%BF%CE%BA%CE%BA%CE%BB%CE%B7%CF%83%CE%B9%CE%AC-%CE%BA%CE%B1%CE%BB%CE%B1%CE%BC%CF%80%CE%AC%CE%BA%CE%B1%CF%82,-%CE%BE%CE%AD%CF%83%CF%80%CE%B1%CF%83%CE%B5-%CF%84%CE%BF-%CE%B2%CF%81%CE%AC%CE%B4%CF%85-%CF%84%CE%B7%CF%82-%CE%B4%CE%B5%CF%85%CF%84%CE%AD%CF%81%CE%B1%CF%82-7-9 ; https://www.cnn.gr/ellada/story/551315/fotia-stin-asprokklisia-kalampakas-kinitopoiithikan-epigeies-pyrosvestikes-dynameis ; https://www.enikos.gr/society/fotia-se-dasiki-ektasi-stin-kalabaka-megali-kinitopoiisi-tis-pyrosvestikis/2640485/ ; https://www.naftemporiki.gr/society/2158624/pyrkagia-se-dasiki-ektasi-stin-asprokklisia-kalampakas/ ; https://www.in.gr/2026/09/07/greece/fotia-stin-asprokklisia-kalampakas ; https://www.newsbomb.gr/ellada/story/1761801/foties-olonyxtia-i-maxi-ton-pyrosveston-sta-pyrina-metopa-red-code-simera-se-polles-perioxes | W22: Ξέσπασε βράδυ Δευτέρας 7/9, ~21:15. Κινητοποίηση μόνο επίγειων δυνάμεων. Αεροπλάνα δεν αναφέρθηκαν (νυκτερινή επιχείρηση). | Ξέσπασε βράδυ 7/9. Στις 8/9 επιχειρούσαν ακόμα 20 πυρ. με 7 οχήματα. | ⚠ pyr_postfix 2026-09-23: έκταση μη δημοσιευμένη· η κλίμακα απόκρισης (≤25 πυροσβέστες, ≤4 εναέρια, ≤12 οχήματα) αποκλείει μεγάλο συμβάν. Το «<10 ha» είναι ΣΥΜΠΕΡΑΣΜΑ, όχι μέτρηση, και δεν προσμετράται στα αθροίσματα. | X22: 2026-09-08 | Y22: 9 | Z22: 0 | AA22: =IF('Στατιστικά'!$C$6,1,IFERROR(INDEX('Στατιστικά'!$C$10:$C$83,MATCH(G22,'Στατιστικά'!$B$10:$B$83,0))*1,0)) -> 1
A23: 46272 | B23: 15:30 | E23: Βρυζέικα Αλεξανδρούπολης | F23: Ανατολική Μακεδονία και Θράκη | G23: Έβρου | H23: Αλεξανδρούπολης | I23: 36 | J23: 14 | K23: 4 | L23: 1 | M23: 16 τμήματα πεζοπόρων 2ης & 21ης ΕΜΟΔΕ | N23: Δήμος Αλεξανδρούπολης (υδροφόρες), Περιφέρεια, Στρατός | Q23: 3 | R23: ΥΨΗΛΗ | S23: υπό έλεγχο | V23: https://www.ertnews.gr/perifereiakoi-stathmoi/orestiada/aleksandroupoli-fotia-stin-perioxi-vryzeika/ ; https://www.naftemporiki.gr/society/2158382/alexandroypoli-pyrkagia-konta-stin-egnatia-odo/ ; https://www.newsbomb.gr/ellada/story/1761687/fotia-tora-se-dasos-stin-aleksandroypoli-kaiei-konta-stin-egnatia-odo ; https://civilprotection.gov.gr/sites/default/files/2026-09/260907.jpg ; https://pameevro.gr/alexandroupoli-fotia-vryzeika/ ; https://www.imerodromos.gr/fotia-stin-alexandroupoli/ ; https://voicenews.gr/alexandroupoli-pyrkagia-se-dasiki-ektasi/ ; https://www.documentonews.gr/article/foties-tria-energa-metopa-se-evvoia-alexandroupoli-kai-drama-synechis-enischysi-ton-pyrosvestikon-dynameon/ ; https://www.libre.gr/2026/09/07/fotia-stin-alexandroupoli-4/ | W23: Κοντά στην Εγνατία Οδό· μεγάλο τμήμα της περιοχής είχε καεί σε πυρκαγιά 2023 | Μεγάλο μέρος ζώνης ήδη καμένο από πυρκαγιές 2023. Μετά κατάσβεση, τα 4 εναέρια ανακατευθύνθηκαν στη Δράμα. | X23: 2026-09-08 | Y23: 9 | Z23: 0 | AA23: =IF('Στατιστικά'!$C$6,1,IFERROR(INDEX('Στατιστικά'!$C$10:$C$83,MATCH(G23,'Στατιστικά'!$B$10:$B$83,0))*1,0)) -> 1
A24: 46272 | B24: 15:15 | E24: Υψηλή Ράχη Δράμας | F24: Ανατολική Μακεδονία και Θράκη | G24: Δράμας | I24: 42 | J24: 8 | K24: 4 | L24: 1 | M24: 3 ομάδες πεζοπόρων 2ης & 21ης ΕΜΟΔΕ | N24: τοπικές υδροφόρες | Q24: 3 | R24: ΥΨΗΛΗ | S24: σε εξέλιξη | V24: https://www.eleftherostypos.gr/ellada/pyrkagia-sti-drama-8-ochimata-pezopora-tmimata-kai-enaeria-mesa-sti-machi-tis-katasvesis ; https://pelop.gr/fotia-drama-ypsili-rachi-dyo-esties/ ; https://www.paraskhnio.gr/2026/09/07/drama-dyo-esties-pyrkagias-se-dasiki-ektasi-stin-ypsili-rachi/ ; https://civilprotection.gov.gr/sites/default/files/2026-09/260907.jpg ; https://www.documentonews.gr/article/fotia-tora-stin-ypsili-rachi-tis-dramas-dyo-diaforetikes-esties-se-dasiki-ektasi/ ; https://newpost.gr/eidiseis/pyrinos-efialtis-se-tessera-metopa-machi-me-tis-floges-se-eyvoia-drama-alexandroypoli-kai-konitsa-vinteo/ ; https://www.ertnews.gr/eidiseis/synagermos-stin-pyrosvestiki-gia-fotia-sti-drama-dyo-esties-stin-ypsili-raxi/ ; https://www.newsbeast.gr/greece/arthro/13340449/diplo-metopo-fotias-stin-ypsili-rachi-tis-dramas | W24: Δύο ξεχωριστές εστίες σε μικρή απόσταση· αεροσκάφη αντλούν νερό από Καβάλα | Δύο διαφορετικές εστίες στη δασική έκταση Υψηλής Ράχης. Εναέρια ενισχύθηκαν από Αλεξανδρούπολη. Eleftheros Typos: 8 οχήματα. | Δύο ξεχωριστές εστίες σε δασική έκταση, κοντινή απόσταση μεταξύ τους. Συναγερμός Πυροσβεστικής 07/09/2026. | X24: 2026-09-23 | Y24: 9 | Z24: 0 | AA24: =IF('Στατιστικά'!$C$6,1,IFERROR(INDEX('Στατιστικά'!$C$10:$C$83,MATCH(G24,'Στατιστικά'!$B$10:$B$83,0))*1,0)) -> 1
A25: 46272 | B25: 14:30 | E25: Μακρυκάπα Εύβοιας | F25: Στερεά Ελλάδα | G25: Ευβοίας | H25: Διρφύων-Μεσσαπίων | I25: 92 | J25: 32 | K25: 10 | L25: 4 | M25: 2 ομάδες πεζοπόρων | N25: Δήμος Διρφύων-Μεσσαπίων (υδροφόρες, βαρέα μηχανήματα) | Q25: 4 | R25: ΠΟΛΥ ΥΨΗΛΗ | S25: υπό έλεγχο | T25: υπό διερεύνηση (ΔΑΕΕ) | U25: 112 7/9 14:55: ενημέρωση ευρύτερης περιοχής πυρκαγιάς· 112 7/9 15:11: εκκένωση οικισμού Τριάδας προς Ψαχνά | 112 14:55 07-09: πληροφοριακό μήνυμα ευρύτερης περιοχής Μακρυκάπας· 112 15:11 07-09: εκκένωση οικισμού Τριάδας προς Ψαχνά | 112: εκκένωση κατοίκων Τριάδας προς Ψαχνά | 07/09 ~14:55: ενημερωτικό μήνυμα 112 σε κατοίκους ευρύτερης περιοχής Μακρυκάπας Εύβοιας | V25: https://www.eleftherostypos.gr/ellada/makrykapa-evvoias-92-pyrosvestes-kai-14-enaeria-mesa-epicheiroun-sti-fotia ; https://www.enikos.gr/society/evvoia-anexelegkti-i-fotia-metaxy-makrykapas-kai-triadas-enischythikan-oi-dynameis-anafores-gia-zimies-se-egkatastaseis-kai-kalliergeies/2640306/ ; https://www.paraskhnio.gr/2026/09/07/fotia-stin-evvoia-ekkenonetai-i-triada-minyma-tou-112-pros-tous-katoikous/ ; https://www.enikos.gr/society/fotia-se-pefkodasos-stin-evvoia-minyma-apo-to-112-gia-etoimotita-vinteo/2640169/ ; https://newpost.gr/eidiseis/eyvoia-megali-fotia-sti-makrykapa-ischyres-epigeies-kai-enaeries-dynameis/ ; https://civilprotection.gov.gr/sites/default/files/2026-09/260907.jpg ; https://www.ertnews.gr/roi-idiseon/pyrkagia-se-dasiki-ektasi-stin-perioxi-makrykapa-eyvoias-ixise-to-112/ ; https://www.ertnews.gr/roi-idiseon/pyrkagia-sti-makrykapa-eyvoias-minyma-112-gia-apomakrynsi-apo-triada-pros-psaxna/ ; https://www.zougla.gr/greece/se-yfesi-i-pyrkagia-stin-evvoia/ ; https://www.voliotaki.gr/2026/09/%CF%83%CE%B5-%CF%8D%CF%86%CE%B5%CF%83%CE%B7-%CE%B7-%CF%80%CF%85%CF%81%CE%BA%CE%B1%CE%B3%CE%B9%CE%AC-%CF%83%CF%84%CE%B7%CE%BD-%CE%B5%CF%8D%CE%B2%CE%BF%CE%B9%CE%B1.html ; https://www.newsit.gr/ellada/fotia-stin-eyvoia-stin-perioxi-makrykapa-ixise-to-112-gia-ekkenosi-apo-tin-triada-pros-psaxna-enisxythikan-oi-dynameis/4768125/ ; https://www.naftemporiki.gr/society/2158360/eyvoia-fotia-tora-sti-makrykapa-minyma-toy-112/ ; https://www.efsyn.gr/ellada/1462122/pyrkagia-se-dasiki-ektasi-sti-makrykapa-eyvoias-ihise-to-112-sikothikan-5-enaeria-mesa/ ; https://newpost.gr/eidiseis/pyrinos-efialtis-se-tessera-metopa-machi-me-tis-floges-se-eyvoia-drama-alexandroypoli-kai-konitsa-vinteo/ | W25: Ανεξέλεγκτη· καίει πευκοδάσος· κίνδυνος επέκτασης προς Πισσώνα· ζημιές σε εγκαταστάσεις και καλλιέργειες· ΓΕΣ κινητοποιήθηκε | Αρχική κινητοποίηση 55 πυρ + 17 οχ + 2 αεροσκ + 3 ελικ (14:30–14:55). Δυνάμεις ενισχύθηκαν σε 92 πυρ / 32 οχ / 10+4 εναέρια μετά το 112 εκκένωσης. Κατάσταση σε ύφεση αργότερα. | Ανεξέλεγκτη αρχικά — δυνατοί άνεμοι, πυκνός καπνός. Ζημιές σε αγροτικές εγκαταστάσεις/καλλιέργειες. Κίνδυνος επέκτασης προς Πισσώνα. Αργότερα σε ύφεση/χωρίς ενεργό μέτωπο. | Ενεργοποίηση ΔΑΕΕ Εύβοιας για διερεύνηση. Στις 8/9: χωρίς ενεργό μέτωπο, μόνο διάσπαρτες εστίες. Αρχικές δυνάμεις: 55 πυρ., 17 οχ., 2 α/φ, 3 ελικ. | X25: 2026-09-08 | Y25: 9 | Z25: 0 | AA25: =IF('Στατιστικά'!$C$6,1,IFERROR(INDEX('Στατιστικά'!$C$10:$C$83,MATCH(G25,'Στατιστικά'!$B$10:$B$83,0))*1,0)) -> 1
A26: 46272 | B26: 12:00 | E26: Άγιος Αθανάσιος Εύβοιας | F26: Στερεά Ελλάδα | G26: Ευβοίας | H26: Διρφύων-Μεσσαπίων | I26: 25 | J26: 5 | K26: 0 | L26: 1 | M26: 2 ομάδες πεζοπόρων | P26: <10 ha | Q26: 4 | R26: ΠΟΛΥ ΥΨΗΛΗ | S26: σε εξέλιξη | V26: https://www.ertnews.gr/eidiseis/eyvoia-pyrkagia-se-xamili-vlastisi-ston-agio-athanasio/ ; https://civilprotection.gov.gr/sites/default/files/2026-09/260907.jpg | W26: Χαμηλή βλάστηση· ίδιος δήμος με Μακρυκάπα αλλά διαφορετική τοποθεσία και ώρα | ⚠ pyr_postfix 2026-09-23: έκταση μη δημοσιευμένη· η κλίμακα απόκρισης (≤25 πυροσβέστες, ≤4 εναέρια, ≤12 οχήματα) αποκλείει μεγάλο συμβάν. Το «<10 ha» είναι ΣΥΜΠΕΡΑΣΜΑ, όχι μέτρηση, και δεν προσμετράται στα αθροίσματα. | X26: 2026-09-07 | Y26: 9 | Z26: 0 | AA26: =IF('Στατιστικά'!$C$6,1,IFERROR(INDEX('Στατιστικά'!$C$10:$C$83,MATCH(G26,'Στατιστικά'!$B$10:$B$83,0))*1,0)) -> 1
A27: 46272 | B27: 11:30 | E27: Κωφοί Μαγνησίας | F27: Θεσσαλία | G27: Μαγνησίας | H27: Αλμυρού | I27: 35 | J27: 10 | K27: 3 | L27: 1 | M27: 2 ομάδες πεζοπόρων 10ης ΕΜΟΔΕ | N27: Δήμος Αλμυρού (υδροφόρες) | Q27: 5 | R27: ΚΑΤΑΣΤΑΣΗ ΣΥΝΑΓΕΡΜΟΥ | S27: οριοθετήθηκε | V27: https://www.newsit.gr/ellada/fotia-sti-magnisia-stin-perioxi-kofoi-sti-maxi-kai-3-aeroskafi/4767882/ ; https://www.newsbomb.gr/ellada/story/1761626/fotia-stous-kofoys-magnisias-epixeiroyn-kai-tessera-enaeria-mesa ; https://www.ertnews.gr/perifereiakoi-stathmoi/volos/se-kokkino-synagermo-magnisia-kai-sporades-gia-ton-kindyno-pyrkagias/ ; https://civilprotection.gov.gr/sites/default/files/2026-09/260907.jpg ; https://www.protothema.gr/greece/article/1875026/fotia-se-dasiki-ektasi-sti-magnisia-epiheiroun-tessera-enaeria-mesa/ ; https://newpost.gr/eidiseis/magnisia-oriothetithike-i-pyrkagia-se-dasiki-ektasi-stin-periochi-kofoi/ ; https://pelop.gr/magnisia-fotia-stous-kofous-epicheiroun-35-pyrosvestes-kai-tessera-enaeria-mesa/ | W27: Μαγνησία και Σποράδες σε «κόκκινο συναγερμό» (κατ. 5) κατά ertnews· ΔΑΕΕ ενεργοποιήθηκε για διερεύνηση αιτίων | Ώρα ειδοποίησης Πυροσβεστικής ~11:30. ΔΑΕΕ Μαγνησίας για διερεύνηση αιτίων. | X27: 2026-09-08 | Y27: 9 | Z27: 0 | AA27: =IF('Στατιστικά'!$C$6,1,IFERROR(INDEX('Στατιστικά'!$C$10:$C$83,MATCH(G27,'Στατιστικά'!$B$10:$B$83,0))*1,0)) -> 1
A28: 46272 | B28: 09:45 | C28: 11:00 | E28: Ελαιοχώρι Καβάλας | F28: Ανατολική Μακεδονία και Θράκη | G28: Καβάλας | H28: Καβάλας | I28: 18 | J28: 5 | K28: 2 | L28: 1 | M28: 1 ομάδα 21ης ΕΜΟΔΕ | N28: Δήμος (υδροφόρες) | P28: <10 ha | Q28: 3 | R28: ΥΨΗΛΗ | S28: υπό έλεγχο | T28: υπό διερεύνηση | U28: 112 (07/09 πρωί): ετοιμότητα κατοίκων Ελαιοχωρίου Καβάλας | 112 7/9: ετοιμότητα κατοίκων Ελαιοχωρίου Καβάλας (χωρίς εντολή εκκένωσης) | V28: https://www.ertnews.gr/eidiseis/ellada/fotia-sto-elaioxori-kavalas-minyma-apo-to-112-stous-katoikous-na-vriskontai-se-etoimotita/ ; https://www.in.gr/2026/09/07/greece/fotia-sto-elaioxori-kavalas-epixeiroun-tria-enaeria/ ; https://newpost.gr/eidiseis/pyrkagia-se-dasiki-ektasi-sto-elaiochori-kavalas/ ; https://www.flash.gr/fotia-tora-sto-elaiochori-kavalas-minyma-toy-112-stoys-katoikoys-1080116 ; https://parallaximag.gr/epikairotita/greece/kavala-minyma-112-gia-tin-pyrkagia-se-dasiki-ektasi-sto-elaiochori ; https://civilprotection.gov.gr/sites/default/files/2026-09/260907.jpg ; https://www.paggaio.news/%CF%80%CF%85%CF%81%CE%BA%CE%B1%CE%B3%CE%B9%CE%AC-%CF%83%CE%B5-%CE%B4%CE%B1%CF%83%CE%B9%CE%BA%CE%AE-%CE%AD%CE%BA%CF%84%CE%B1%CF%83%CE%B7-%CF%83%CF%84%CE%BF-%CE%B5%CE%BB%CE%B1%CE%B9%CE%BF%CF%87%CF%8E-2/ ; https://www.ertnews.gr/roi-idiseon/fotia-sto-elaioxori-kavalas-anagkastiki-prosgeiosi-pyrosvestikou-elikopterou-ereynontai-ta-aitia/ ; https://www.naftemporiki.gr/society/2158624/pyrkagia-se-dasiki-ektasi-stin-asprokklisia-kalampakas/ | W28: Δασική έκταση. 3 εναέρια = 2 αεροσκάφη + 1 ελικόπτερο. Άρθρο ertnews.gr: 10:32 07/09. Κίνδυνος (07/09 χάρτης ΓΓΠΠ): Καβάλας κίτρινο=3. | Δασική έκταση· newsit ανέφερε «χωρίς ενεργό μέτωπο»· Θάσος σε κατ. 4 ενώ Καβάλα σε κατ. 3 | Πυρκαγιά στην περιοχή «Προφήτης Ηλίας». Αναγκαστική προσγείωση πυροσβεστικού ελικοπτέρου κατά τη διάρκεια κατάσβεσης (χωρίς αναφορά τραυματισμών). Υπό έλεγχο ~11:00. | ⚠ pyr_postfix 2026-09-23: έκταση μη δημοσιευμένη· η κλίμακα απόκρισης (≤25 πυροσβέστες, ≤4 εναέρια, ≤12 οχήματα) αποκλείει μεγάλο συμβάν. Το «<10 ha» είναι ΣΥΜΠΕΡΑΣΜΑ, όχι μέτρηση, και δεν προσμετράται στα αθροίσματα. | X28: 2026-09-08 | Y28: 9 | Z28: 0 | AA28: =IF('Στατιστικά'!$C$6,1,IFERROR(INDEX('Στατιστικά'!$C$10:$C$83,MATCH(G28,'Στατιστικά'!$B$10:$B$83,0))*1,0)) -> 1
A29: 46272 | E29: Διασέλλα | F29: Πελοπόννησος | G29: Ηλείας | I29: 75 | J29: 22 | K29: 6 | L29: 1 | M29: 3 ορειβατικές ομάδες 18ης ΕΜΟΔΕ | Q29: 3 | R29: ΥΨΗΛΗ | S29: σε εξέλιξη | V29: https://www.ertnews.gr/perifereiakoi-stathmoi/pirgos/diimero-me-polles-pyrkagies-stin-ileia/ | W29: Ξεχωριστό μέτωπο από Σκιλλούντια. Αναφέρεται σε άρθρο ertnews 07/09. Επίσης πυρκαγιά σε Κάτω Σαμικό & Αγρίδια ταυτόχρονα. | Χαρακτηρίστηκε ως η «σημαντικότερη και πιο απαιτητική» πυρκαγιά του διημέρου 06–07/09 στην Ηλεία (ertnews). Ημερομηνία εκτιμάται 07/09 βάσει διημέρου άρθρου. | X29: 2026-09-23 | Y29: 9 | Z29: 0 | AA29: =IF('Στατιστικά'!$C$6,1,IFERROR(INDEX('Στατιστικά'!$C$10:$C$83,MATCH(G29,'Στατιστικά'!$B$10:$B$83,0))*1,0)) -> 1
A30: 46272 | C30: 11:00 | E30: Ελαιοχώρι (Προφήτης Ηλίας) | F30: Ανατολική Μακεδονία και Θράκη | G30: Καβάλας | H30: Παγγαίου | I30: 18 | J30: 5 | K30: 2 | L30: 1 | M30: 1 ομάδα πεζοπόρων 21ης ΕΜΟΔΕ | N30: υδροφόρες τοπικής αυτοδιοίκησης | Q30: 3 | R30: ΥΨΗΛΗ | S30: υπό έλεγχο | V30: https://www.paggaio.news/%CF%80%CF%85%CF%81%CE%BA%CE%B1%CE%B3%CE%B9%CE%AC-%CF%83%CE%B5-%CE%B4%CE%B1%CF%83%CE%B9%CE%BA%CE%AE-%CE%AD%CE%BA%CF%84%CE%B1%CF%83%CE%B7-%CF%83%CF%84%CE%BF-%CE%B5%CE%BB%CE%B1%CE%B9%CE%BF%CF%87%CF%8E-2/ | W30: Πρωινό περιστατικό, υπό έλεγχο λίγο μετά τις 11:00. Περιοχή «Προφήτης Ηλίας». | ⚠ pyr_postfix 2026-09-23: διπλοεγγραφή του ίδιου συμβάντος· η έκταση δεν προσμετράται (_έκταση0=0). Φέρουσα εγγραφή: γραμμή 28. | X30: 2026-09-08 | Y30: 9 | Z30: 0 | AA30: =IF('Στατιστικά'!$C$6,1,IFERROR(INDEX('Στατιστικά'!$C$10:$C$83,MATCH(G30,'Στατιστικά'!$B$10:$B$83,0))*1,0)) -> 1
A31: 46272 | C31: 12:48 | E31: Μουρίκι | F31: Δυτική Ελλάδα | G31: Αχαΐας | H31: Καλαβρύτων | I31: 21 | J31: 6 | K31: 0 | L31: 1 | M31: 1 ομάδα πεζοπόρων 6ης ΕΜΟΔΕ | N31: υδροφόρες Δήμου Καλαβρύτων | P31: <10 ha | Q31: 4 | R31: ΠΟΛΥ ΥΨΗΛΗ | S31: οριοθετήθηκε | T31: υπό διερεύνηση (Ανακριτικό Κλιμάκιο Αντιμετώπισης Εγκλημάτων Εμπρησμού Αχαΐας) | V31: https://pelop.gr/achaia-fotia-sto-mouriki-epicheiroun-21-pyrosvestes-kai-elikoptero/ ; https://www.newsit.gr/ellada/oriothetithike-i-fotia-sto-mouriki-axaias-kinitopoiithikan-21-pyrosvestes/4767855/ ; https://www.naftemporiki.gr/society/2158223/achaia-fotia-tora-sto-moyriki/ ; https://www.eleftherostypos.gr/ellada/oriothetithikan-oi-foties-se-achaia-kai-magnisia ; https://www.kalavrytanews.com/2026/09/blog-post_241.html | W31: Οριοθετήθηκε μέχρι τις 12:48 της 7/9. | ⚠ pyr_postfix 2026-09-23: έκταση μη δημοσιευμένη· η κλίμακα απόκρισης (≤25 πυροσβέστες, ≤4 εναέρια, ≤12 οχήματα) αποκλείει μεγάλο συμβάν. Το «<10 ha» είναι ΣΥΜΠΕΡΑΣΜΑ, όχι μέτρηση, και δεν προσμετράται στα αθροίσματα. | X31: 2026-09-08 | Y31: 9 | Z31: 0 | AA31: =IF('Στατιστικά'!$C$6,1,IFERROR(INDEX('Στατιστικά'!$C$10:$C$83,MATCH(G31,'Στατιστικά'!$B$10:$B$83,0))*1,0)) -> 1
A32: 46271 | B32: 17:01 | C32: 17:16 | E32: Άγιο Όρος Χαλκιδικής | F32: Κεντρική Μακεδονία | G32: Χαλκιδικής | H32: Αγίου Όρους | I32: 32 | J32: 9 | K32: 4 | L32: 2 | M32: 2 ομάδες πεζοπόρων 2ης ΕΜΟΔΕ | Q32: 2 | R32: ΜΕΣΗ | S32: υπό έλεγχο | T32: καύση απορριμμάτων (σύλληψη 53χρονου) | V32: https://www.skai.gr/ ; https://www.newsit.gr/ellada/ypo-elegxo-i-fotia-sto-agio-oros-epixeirisan-6-enaeria-mesa/4766278/ ; https://www.newsbomb.gr/ellada/story/1761244/pyrkagia-sto-agio-oros-megali-pyrosvestiki-epicheirisi-ripseis-apo-6-enaeria-mesa ; https://www.rthess.gr/ellada/syllipsi-gia-pyrkagia-sto-agio-oros-sti-chalkidiki/ ; https://www.xalkidikipolitiki.com/fotia-agio-oros-paparnika/ ; https://messolonghivoice.gr/dasiki-pyrkagia-sto-agio-oros-se-pliri-exelixi-i-epicheirisi-katasvesis-me-6-enaeria-mesa ; https://www.skai.gr | W32: Επεκτάθηκε σε ξηρό γρασίδι και καλάμια. Συνελήφθη 53χρονος για εμπρησμό από καύση απορριμμάτων. Πηγή: Yutori/skai.gr (δεν εντοπίστηκε αυτοτελές άρθρο). ΓΓΠΠ 06/09 Χαλκιδικής: μπλε (2). | Εξάπλωση σε ξηρό γρασίδι και καλάμια. Σύλληψη 53χρονου. Danger_level βάσει χάρτη ΓΓΠΠ 06/09/2026 (Χαλκιδική=μπλε). | Εξάπλωση σε ξηρό χόρτο και καλάμια. Σύλληψη δράστη. Δεδομένα δυνάμεων δεν αναφέρθηκαν από Yutori. | Εξάπλωση σε ξηρό γρασίδι και καλάμια. 53χρονος συνελήφθη ως υπαίτιος. | X32: 2026-09-08 | Y32: 9 | Z32: 0 | AA32: =IF('Στατιστικά'!$C$6,1,IFERROR(INDEX('Στατιστικά'!$C$10:$C$83,MATCH(G32,'Στατιστικά'!$B$10:$B$83,0))*1,0)) -> 1
A33: 46271 | B33: 17:01 | E33: Αγίου Όρους | F33: Κεντρική Μακεδονία | G33: Χαλκιδικής | Q33: 2 | R33: ΜΕΣΗ | S33: υπό έλεγχο | T33: Καύση απορριμμάτων (53χρονος συνελήφθη) | V33: https://www.skai.gr/ | W33: Εξαπλώθηκε σε ξηρό γρασίδι και καλάμια. Σύλληψη δράστη. | X33: 2026-09-08 | Y33: 9 | Z33: 0 | AA33: =IF('Στατιστικά'!$C$6,1,IFERROR(INDEX('Στατιστικά'!$C$10:$C$83,MATCH(G33,'Στατιστικά'!$B$10:$B$83,0))*1,0)) -> 1
A34: 46271 | B34: 16:51 | E34: Σκιλλούντια (Αρχαία Σκιλλούς) | F34: Πελοπόννησος | G34: Ηλείας | H34: Ανδρίτσαινα-Κρεστένων | I34: 45 | J34: 19 | K34: 10 | L34: 0 | M34: 3 ορειβατικές ομάδες 18ης ΕΜΟΔΕ | N34: υδροφόρες Δήμου Ανδρίτσαινας | O34: ναι | Q34: 3 | R34: ΥΨΗΛΗ | S34: σε εξέλιξη | U34: 06/09 ~17:30: μήνυμα 112 ετοιμότητας σε κατοίκους Σκιλλούντιας Ηλείας | V34: https://www.newsit.gr/ellada/fotia-stin-perioxi-skillountia-ileias-ixise-to-112-gia-etoimotita-stin-maxi-kai-10-aeroskafi/4767235/ ; https://www.flash.gr/ileia-fotia-megalon-diastaseon-sti-skilloyntia-minyma-etoimotitas-apo-to-112-1080046 ; https://www.ertnews.gr/perifereiakoi-stathmoi/pirgos/diimero-me-polles-pyrkagies-stin-ileia/ ; https://www.in.gr/2026/09/06/greece/fotia-stin-ileia-sti-maxi-eksi-enaeria/ | W34: 10 εναέρια: 5 Canadair + 5 Air Tractor. ΕΣΚΕΔΙΚ παρακολουθεί με drone (οπτικό και θερμικό). Ανάλυση ΔΑΕΕ Ηλείας για αιτία. | X34: 2026-09-08 | Y34: 9 | Z34: 0 | AA34: =IF('Στατιστικά'!$C$6,1,IFERROR(INDEX('Στατιστικά'!$C$10:$C$83,MATCH(G34,'Στατιστικά'!$B$10:$B$83,0))*1,0)) -> 1
A35: 46271 | B35: 16:15 | D35: 17:08 | E35: Πινεία Ηλείας | F35: Δυτική Ελλάδα | G35: Ηλείας | H35: Ήλιδας | I35: 25 | J35: 10 | K35: 6 | N35: Δήμος Ήλιδας: υδροφόρες | Q35: 3 | R35: ΥΨΗΛΗ | S35: κατασβέστηκε | T35: υπό διερεύνηση (ΔΑΕΕ Ηλείας) | V35: https://www.newsit.gr/ellada/ileia-deyteri-fotia-stin-perioxi-pineia-oriothetithike-i-fotia-stin-perioxi-skillountia/4767259/ ; https://www.newsbomb.gr/ellada/story/1761475/ileia-pyrkagia-stin-perioxi-tis-pineias-epixeiroyn-6-aeroskafi ; https://www.parapolitika.gr/ellada/article/1786979/fotia-stin-pineia-ileias-kinitopoiithikan-kai-enaeria-mesa ; https://www.skai.gr ; https://www.newsit.gr/ellada/ileia-deyteri-fotia-stin-perioxi-pineia-mainetai-i-fotia-stin-perioxi-skillountia/4767259/ ; https://www.ertnews.gr/eidiseis/ellada/fotia-stin-pineia-ileias/ ; https://www.in.gr/2026/09/06/greece/fotia-stin-ileia-sti-maxi-eksi-enaeria/ ; https://www.efsyn.gr/ellada/1461467/fotia-stin-pineia-ileias-epiheiroyn-exi-aeroskafi/ ; https://www.cnn.gr/ellada/story/551109/nea-fotia-stin-pineia-ileias-sikothikan-eksi-aeroskafi ; https://www.tanea.gr/2026/09/06/greece/diplo-pyrino-metopo-stin-ileia-enisxysi-ton-pyrosvestikon-dynameon-kai-112-stin-skillountia-maxi-stin-pineia ; https://www.skai.gr/ | W35: Χαμηλή βλάστηση. Πλήρης κατάσβεση ~17:08 EEST. Διερεύνηση αιτίων ΔΑΕΕ Ηλείας. ΓΓΠΠ 06/09 Ηλείας: κίτρινο (3). | Πλήρης κατάσβεση εντός 6/9. Σύγχρονη με την πυρκαγιά Σκιλλούντιας. Danger_level βάσει χάρτη ΓΓΠΠ 06/09/2026 (Ηλεία=κίτρινο). | Χαμηλή βλάστηση. Πλήρης κατάσβεση εντός 06/09 (Yutori: «εξαλειφθείσα»). Διερεύνηση αιτίας από ΔΑΕΕ Ηλείας. Κίνδυνος (06/09 χάρτης ΓΓΠΠ): Ηλείας κίτρινο=3. | Δεύτερη φωτιά στην Πηνεία ξεκίνησε ~16:15. Γρήγορη κατάσβεση. Χαμηλή βλάστηση. ΔΑΕΕ Ηλείας ερεύνησε αιτίες. | Πλήρης κατάσβεση εντός της ίδιας ημέρας. Διερεύνηση αιτίων από ΔΑΕΕ Ηλείας. | Πλήρης κατάσβεση. Διερεύνηση αιτίων από ΔΑΕΕ Ηλείας. | X35: 2026-09-08 | Y35: 9 | Z35: 0 | AA35: =IF('Στατιστικά'!$C$6,1,IFERROR(INDEX('Στατιστικά'!$C$10:$C$83,MATCH(G35,'Στατιστικά'!$B$10:$B$83,0))*1,0)) -> 1
A36: 46271 | B36: 16:00 | E36: Σκιλλούντια Ηλείας | F36: Δυτική Ελλάδα | G36: Ηλείας | H36: Ζαχάρω | I36: 45 | J36: 16 | K36: 10 | M36: 3 ορειβατικές ομάδες 18ης ΕΜΟΔΕ | N36: Δήμος Ανδριτσαίνης (υδροφόρες) | O36: εθελοντές | Q36: 3 | R36: ΥΨΗΛΗ | S36: σε εξέλιξη | T36: υπό διερεύνηση | U36: 112 μήνυμα ετοιμότητας κατοίκων Σκιλλούντιας | 112 06/09 ~17:25: ετοιμότητα κατοίκων Σκιλλούντιας Ηλείας (δεν εκδόθηκε εντολή εκκένωσης) — εστάλη και δεύτερο μήνυμα 112 αργότερα | 112 (~17:30 06/09): ετοιμότητα κατοίκων Σκιλλούντιας | 112 ~17:30 06-09: ετοιμότητα κατοίκων Σκιλλουντίας | 112 (~17:30): ετοιμότητα κατοίκων περιοχής | V36: https://www.in.gr/2026/09/06/greece/fotia-stin-ileia-sti-maxi-eksi-enaeria/ ; https://ertnews.gr/perifereiakoi-stathmoi/pirgos/fotia-sti-skillounta-ileias ; https://www.tanea.gr/2026/09/06/greece/diplo-pyrino-metopo-stin-ileia-enisxysi-ton-pyrosvestikon-dynameon-kai-112-stin-skillountia-maxi-stin-pineia ; https://www.newsit.gr/ellada/ileia-deyteri-fotia-stin-perioxi-pineia-oriothetithike-i-fotia-stin-perioxi-skillountia/4767259/ ; https://www.news24world.com/fotia-tora-stin-palia-skillountia-ileias-megali-kinitopoiisi-tis-pyrosvestikis-epicheiroun-6-aeroplana/ ; https://www.newsit.gr/ellada/fotia-stin-perioxi-skillountia-ileias-ixise-to-112-gia-etoimotita-stin-maxi-kai-10-aeroskafi/4767235/ ; https://www.flash.gr/ileia-fotia-megalon-diastaseon-sti-skilloyntia-minyma-etoimotitas-apo-to-112-1080046 ; https://www.ertnews.gr/perifereiakoi-stathmoi/pirgos/fotia-sti-skillountia-ileias-enisxythikan-oi-dynameis/ ; https://lawandorder.gr/ileia-choris-energo-metopo-i-fotia-skillountia-6-9/ ; https://todaypress.gr/2026/09/06/fotia-stin-ileia-neo-minyma-112-gia-ti-skillountia-se-etoimotita-oi-katoikoi/ ; https://www.protothema.gr ; https://www.skai.gr ; https://x.com/112Greece/status/2096606146849124849 ; https://www.mononews.gr/society/fotia-stin-ileia-112-gia-etoimotita-stin-skillountia-enischythikan-oi-dynameis-tis-pyrosvestikis ; https://www.topontiki.gr/2026/09/06/fotia-tora-stin-periochi-skillounta-ilias-epichiroun-6-enaeria-mesa/ ; https://www.reader.gr/ellada/fotia-stin-ileia-minyma-toy-112-gia-etoimotita-sti-skilloyntia/660399 ; https://todaypress.gr/2026/09/06/fotia-stin-ileia-mainetai-i-pyrkagia-sti-skillountia-10-aeroskafi-sti-machi-me-tis-floges/ ; https://www.larissanet.gr/2026/09/06/pyrgos-fotia-se-agrotodasiki-ektasi-stin-periochi-skillountia/ ; https://www.enikos.gr/society/fotia-sti-skillountia-ileias-minyma-apo-to-112-gia-etoimotita/2639703/ ; https://pelop.gr/ileia-mainetai-i-fotia-sti-skillountia/ ; https://www.skai.gr/ ; https://www.protothema.gr/ ; https://www.ertnews.gr/perifereiakoi-stathmoi/pirgos/diimero-me-polles-pyrkagies-stin-ileia/ | W36: Αγροτοδασική έκταση. 10 εναέρια συνολικά (Yutori). Drone επιτήρηση θερμικής κάμερας. Αρχικά 38 πυρ./9 οχ./6 εναέρια, ενισχύθηκε σε 45/16/10. Αργότερα οριοθετήθηκε (newsit). ΓΓΠΠ 06/09 Ηλείας: κίτρινο (3). | Πυρκαγιά μεγάλων διαστάσεων. Αριθμοί δυνάμεων αφορούν ενισχυμένη σύνθεση. «Χωρίς ενεργό μέτωπο» βάσει lawandorder.gr. Danger_level βάσει χάρτη ΓΓΠΠ 06/09/2026 (Ηλεία=κίτρινο). | 10 εναέρια συνολικά (split αεροσκαφών/ελικοπτέρων άγνωστος). Ταυτόχρονη πυρκαγιά Πηνείας Ηλείας (δεύτερο μέτωπο). Κίνδυνος (06/09 χάρτης ΓΓΠΠ): Ηλείας κίτρινο=3. | Αναζωπύρωση στην παλιά Σκιλλούντα στα όρια Ανδρίτσαινας-Κρέστενας με ισχυρή ενίσχυση (ανακτήθηκε 38 πυροσβέστες + 19 οχ + 10 αεροσκ κατά τη φάση αναζωπύρωσης). ΔΑΕΕ ερεύνησε αιτία. | 10 εναέρια μέσα συνολικά (χωρίς ανάλυση). Κίνδυνος σε πευκοδάσος. | ⚠ pyr_postfix 2026-09-23: διπλοεγγραφή του ίδιου συμβάντος· η έκταση δεν προσμετράται (_έκταση0=0). Φέρουσα εγγραφή: γραμμή 34. | X36: 2026-09-08 | Y36: 9 | Z36: 0 | AA36: =IF('Στατιστικά'!$C$6,1,IFERROR(INDEX('Στατιστικά'!$C$10:$C$83,MATCH(G36,'Στατιστικά'!$B$10:$B$83,0))*1,0)) -> 1
A37: 46271 | B37: 15:39 | C37: 19:27 | E37: Πετσάκοι Αχαΐας | F37: Δυτική Ελλάδα | G37: Αχαΐας | I37: 30 | J37: 9 | K37: 7 | L37: 1 | M37: 2 ορειβατικές ομάδες 6ης ΕΜΟΔΕ | N37: υδροφόρα Δήμου | O37: εθελοντές | P37: 20 | Q37: 3 | R37: ΥΨΗΛΗ | S37: σε εξέλιξη | T37: υπό διερεύνηση (ΔΑΕΕ Αχαΐας) | V37: https://www.protothema.gr/greece/article/1874743/fotia-stous-petsakous-ahaias-megali-kinitopoiisi-tis-purosvestikis-sikothikan-epta-enaeria/ ; https://www.naftemporiki.gr/society/2157877/fotia-tora-stoys-petsakoys-achaias-epta-enaeria-sti-machi-tis-katasvesis/ ; https://www.aigiovoice.gr/peripou-200-stremmata-dasous-kaikan-stous-petsakous-ypo-elegcho-i-pyrkagia/ ; https://www.newsit.gr/ellada/fotia-stin-axaia-epixeiroun-7-enaeria-stin-perioxi-petsakoi/4767200/ ; https://www.efsyn.gr/ellada/1461529/horis-energo-metopo-i-fotia-tin-periohi-petsakoi-ahaias/ ; https://dete.gr/pyrkagia-stous-petsakous-achaias-sti-machi-epta-enaeria-mesa/ ; https://www.skai.gr ; https://www.protothema.gr ; https://pelop.gr/fotia-petsakoi-achaia-7-enaeria/ ; https://www.paraskhnio.gr/2026/09/06/fotia-stous-petsakous-achaias-megali-kinitopoiisi-tis-pyrosvestikis-epicheiroun-epta-enaeria/ ; https://tempo24.news/fotia-stous-petsakous-achaias-epta-enaeria-sti-machi-tis-katasvesis/ ; https://www.newsbomb.gr/ellada/story/1761475/ileia-pyrkagia-stin-perioxi-tis-pineias-epixeiroyn-6-aeroskafi ; https://www.skai.gr/ ; https://www.protothema.gr/ | W37: Αγροτοδασική έκταση. ~200 στρέμματα = 20 ha δάσους κάηκαν. Κινητοποιήθηκε ΔΑΕΕ Αχαΐας. ΓΓΠΠ 06/09 Αχαΐας: κίτρινο (3). | «Χωρίς ενεργό μέτωπο» από 19:27 στις 6/9. Danger_level ρητά επιβεβαιωμένο ως κατηγορία 3 (πηγή Yutori/skai) και χάρτης ΓΓΠΠ 06/09/2026 (Αχαΐα=κίτρινο). | Αγροτοδασική έκταση. 7 εναέρια = 6 αεροσκάφη + 1 ελικόπτερο (pelop.gr). Κίνδυνος (06/09 χάρτης ΓΓΠΠ): Αχαΐας κίτρινο=3. | Δεδομένα δυνάμεων από Yutori Scout 06-09-2026. Κατηγορία κινδύνου 3 κατά Yutori. | 7 εναέρια μέσα συνολικά (χωρίς ανάλυση αεροσκαφών/ελικοπτέρων). Πηγές email: skai.gr, protothema.gr (αποκωδικοποιημένες από Yutori). | Δυνάμεις σύμφωνα με Yutori/skai. Κατηγορία κινδύνου 3 την ημέρα έναρξης. | X37: 2026-09-08 | Y37: 9 | Z37: 20 | AA37: =IF('Στατιστικά'!$C$6,1,IFERROR(INDEX('Στατιστικά'!$C$10:$C$83,MATCH(G37,'Στατιστικά'!$B$10:$B$83,0))*1,0)) -> 1
A38: 46271 | B38: 13:30 | E38: Κλειδί Βοιωτίας | F38: Στερεά Ελλάδα | G38: Βοιωτίας | I38: 55 | J38: 15 | K38: 8 | L38: 3 | M38: 2 ορειβατικές ομάδες 4ης ΕΜΟΔΕ | Q38: 3 | R38: ΥΨΗΛΗ | S38: υπό έλεγχο | U38: 112 (06/09): ετοιμότητα | V38: https://www.thetoc.gr/koinwnia/article/fotia-sti-boiotia-enisxuthikan-oi-dunameis-sto-kleidi---megali-kinitopoiisi-kai-apo-aeros-ixise-to-112 ; https://pelop.gr/fotia-kleidi-voiotias-112-enaeria/ ; https://www.skaikritis.gr/pyrkagia-se-agrotodasiki-ektasi-sto-kleidi-voiotias-112-gia-etoimotita-epicheiroun-11-enaeria/ ; https://www.libre.gr/2026/09/06/choris-energo-metopo-i-fotia-sto-kleidi/ ; https://www.newsbomb.gr/ellada/story/1761443/pyrkagia-sto-kleidi-voiotias-epixeiroyn-4-enaeria-mesa ; https://www.zarpanews.gr/synagermos-gia-fotia-stin-periochi-kleidi-voiotias-ichise-to-112-sikothikan-enaeria-mesa/ ; https://ecozen.gr/2026/09/megali-fotia-sto-kleidi-voiotias-kai-112-gia-etoimotita/ ; https://www.documentonews.gr/article/fotia-tora-sto-kleidi-voiotias/ | W38: Αγροτοδασική έκταση. Αρχικά 50 πυροσβέστες/4 εναέρια – ενισχύθηκε σε 55/11 εναέρια (8 αεροσκάφη + 3 ελικόπτερα). Τελευταία κατάσταση: χωρίς ενεργό μέτωπο. Κίνδυνος (06/09 χάρτης ΓΓΠΠ): Βοιωτίας κίτρινο=3. | X38: 2026-09-07 | Y38: 9 | Z38: 0 | AA38: =IF('Στατιστικά'!$C$6,1,IFERROR(INDEX('Στατιστικά'!$C$10:$C$83,MATCH(G38,'Στατιστικά'!$B$10:$B$83,0))*1,0)) -> 1
A39: 46271 | B39: 13:30 | E39: Κλειδί Τανάγρας | F39: Στερεά Ελλάδα | G39: Βοιωτίας | H39: Τανάγρας | I39: 55 | J39: 15 | K39: 8 | L39: 3 | M39: 2 ορειβατικές ομάδες 4ης ΕΜΟΔΕ | N39: Δήμος Τανάγρας: υδροφόρες | O39: εθελοντές | Q39: 3 | R39: ΥΨΗΛΗ | S39: υπό έλεγχο | T39: υπό διερεύνηση | U39: 112 13:58: μήνυμα ετοιμότητας κατοίκων Κλειδιού Τανάγρας | V39: https://www.thetoc.gr/koinwnia/article/fotia-sti-boiotia-enisxuthikan-oi-dunameis-sto-kleidi---megali-kinitopoiisi-kai-apo-aeros-ixise-to-112 ; https://newsit.gr/ellada/fotia-sto-kleidi-tanagras-voiotias-minyma-tou-112-gia-etoimotita-enisxythikan-oi-dynameis-epixeiroun-11-enaeria/4767134 ; https://www.tanea.gr/2026/09/06/greece/fotia-sto-kleidi-tanagras-voiotias-stalthike-minyma-apo-to-112-epixeiroun-11-enaeria-mesa ; https://www.in.gr/2026/09/06/greece/fotia-sto-kleidi-voiotias-epixeiroun-4-enaeria-mesa | W39: Αγροτοδασική έκταση. Σύνολο 11 εναέρια κατά κορύφωση. Χωρίς ενεργό μέτωπο αργότερα. Ξεχωριστό περιστατικό από την πυρκαγιά του Phantom (05/09) στην ίδια περιοχή. ΓΓΠΠ 06/09 Βοιωτίας: κίτρινο (3). | X39: 2026-09-06 | Y39: 9 | Z39: 0 | AA39: =IF('Στατιστικά'!$C$6,1,IFERROR(INDEX('Στατιστικά'!$C$10:$C$83,MATCH(G39,'Στατιστικά'!$B$10:$B$83,0))*1,0)) -> 1
A40: 46271 | B40: 10:30 | E40: Δροσοπηγή Αφιδνών | F40: Αττική | G40: Αττικής | H40: Μαραθώνος | I40: 135 | J40: 23 | K40: 2 | L40: 3 | M40: 10 πεζοπόρα τμήματα 1ης ΕΜΟΔΕ | N40: υδροφόρα Δήμου Ωρωπού | O40: ναι | Q40: 3 | R40: ΥΨΗΛΗ | S40: υπό έλεγχο | U40: 112 06/09 10:58: ενημέρωση/προειδοποίηση κατοίκων ευρύτερης περιοχής Αφιδνών (δεν εκδόθηκε εντολή εκκένωσης) | 112 (06/09): ετοιμότητα κατοίκων Αφιδνών/Δροσοπηγής | 112 (~10:30): ετοιμότητα κατοίκων Δροσοπηγής — «Φωτιά στην περιοχή Δροσοπηγής ΠΕ Ανατολικής Αττικής. Παραμείνετε σε ετοιμότητα και ακολουθείτε τις οδηγίες των Αρχών.» | 06/09 10:58: ενημερωτικό μήνυμα 112 για κατοίκους ευρύτερης περιοχής Αφιδνών-Ωρωπού | V40: https://www.ertnews.gr/eidiseis/xoris-energo-metopo-i-pyrkagia-sti-drosopigi-afidnon/ ; https://www.skai.gr ; https://www.ertnews.gr/eidiseis/afidnes-enisxythikan-oi-dynameis-stin-pyrkagia-sti-drosopigi-ixise-to-112-diekopi-i-kykloforia/ ; https://www.emakedonia.gr/attiki-fotia-stis-afidnes-ichise-to-112-diekopi-i-kykloforia ; https://www.capital.gr/epikairotita/4014850/afidnes-enisxuthikan-oi-dunameis-stin-purkagia-sti-drosopigi-ixise-to-112-diakopike-i-kukloforia/ ; https://www.in.gr/2026/09/06/greece/fotia-stis-afidnes-sikothikan-5-enaeria/ ; https://www.tanea.gr/2026/09/06/greece/fotia-stis-afidnes-sti-maxi-kai-enaeria-mesa/ ; https://www.efsyn.gr/ellada/1461287/fotia-stis-afidnes-kinitopoiithikan-pente-enaeria-mesa/ ; https://www.pontosnews.gr/860719/ellada/fotia-sti-drosopigi-afidnon-enischythikan-oi-dynameis-minyma-112/ ; https://tomanifesto.gr/fotia-se-khamili-vlastisi-stis-afidnes-ikhise-to-112-ghia-etoimotita-251199 ; https://www.ekathimerini.com ; https://www.tanea.gr/2026/09/06/greece/fotia-stis-drosopigi-enisxythikan-oi-pyrosvestikes-dynameis-112-gia-etoimotita-poioi-dromoi-einai-kleistoi-video ; https://popaganda.gr/newstrack/greece-newstrack/se-pliri-kinitopoiisi-vrisketai-i-pyrosvestiki-gia-ti-fotia-stis-afidnes ; https://www.ekathimerini.com/ ; https://www.protothema.gr/greece/article/1874633/fotia-tora-stis-afidnes-megali-kinitopoiisi-tis-purosvestikis/ | W40: Χαμηλή βλάστηση. Χωρίς ενεργό μέτωπο (ertnews). Δεν αναφέρθηκαν εκκενώσεις. ΓΓΠΠ 06/09 Αττικής: κίτρινο (3). | Καίει χαμηλή βλάστηση. Δεν αναφέρθηκαν εκκενώσεις. «Χωρίς ενεργό μέτωπο» βάσει ERT. Εναέρια λειτουργούσαν περιοδικά. Danger_level βάσει χάρτη ΓΓΠΠ 06/09/2026 (Αττική=κίτρινο). | Χαμηλή βλάστηση, Δήμος Ωρωπού. Διακοπή κυκλοφορίας Ν.Ε.Ο. Αθηνών-Λαμίας, οδ. Ειρήνης Δροσοπηγής, οδ. Χρυσανθέμων. Διερεύνηση από ΑΑΔΕ Αθηνών. Yutori: «δεν αναφέρθηκαν εκκενώσεις» – ωστόσο 112 ήχησε για ετοιμότητα. Κίνδυνος (06/09 χάρτης ΓΓΠΠ): Αττικής κίτρινο=3. | Καίει χαμηλή βλάστηση. Δεν αναφέρθηκαν εκκενώσεις. Πληροφορίες μόνο από Yutori Scout 06-09-2026 μέσω ekathimerini. | Χαμηλή βλάστηση. Διακοπή κυκλοφορίας ΕΟ Αθηνών-Λαμίας στον κόμβο Δροσοπηγής και οδό Ειρήνης Δροσοπηγής. Email ανέφερε «δεν αναφέρθηκαν εκκενώσεις» αλλά 112 ετοιμότητας εστάλη. | Χωρίς ενεργό μέτωπο αργότερα. Κλειστή η εθνική οδός Αθηνών-Λαμίας (είσοδος Δροσοπηγής), Ιρίνης Δροσοπηγής και Χρυσανθέμων. | X40: 2026-09-08 | Y40: 9 | Z40: 0 | AA40: =IF('Στατιστικά'!$C$6,1,IFERROR(INDEX('Στατιστικά'!$C$10:$C$83,MATCH(G40,'Στατιστικά'!$B$10:$B$83,0))*1,0)) -> 1
...

Sheet Ευρώπη
A1: Ημερομηνία | B1: Ώρα έναρξης | C1: Ώρα ελέγχου | D1: Ώρα κατάσβεσης | E1: Πυρκαγιά / Περιοχή | F1: Περιφέρεια | G1: Νομός | H1: Δήμος | I1: Πυροσβέστες | J1: Οχήματα | K1: Αεροσκάφη | L1: Ελικόπτερα | M1: Επίγειες ομάδες | N1: Δήμοι/Περιφέρειες | O1: Εθελοντές | P1: Καμμένη έκταση (ha) | Q1: Κίνδυνος (1-5) | R1: Κατηγορία κινδύνου | S1: Κατάσταση | T1: Αιτία | U1: 112 (Εκκ./Προειδ.) | V1: Πηγές | W1: Σημειώσεις | X1: Ενημερώθηκε
A2: 46285 | E2: Αναγία-Κλήρος | F2: Λευκωσία | H2: Αναγία / Κλήρος | J2: 9 | K2: 0 | L2: 0 | M2: Πυροσβεστική Υπηρεσία, Τμήμα Δασών, Υπηρεσία Θήρας & Πανίδας | O2: SupportCy, Atlas | P2: 1.5 | S2: υπό έλεγχο | T2: υπό διερεύνηση (Αστυνομία) | V2: https://dialogos.com.cy/megali-kinitopoiisi-gia-fotia-metaxy-anagias-kai-kliroy-ypo-elegcho-i-pyrkagia/ ; https://www.ant1live.com/kypros/koinonia/697524_stahti-enamisi-ektario-gis-ypo-elegho-i-pyrkagia-metaxy-anagia-kai-kliroy ; https://www.tothemaonline.com/Article/473328/prolaban-ta-heirotera-ypo-elegho-h-pyrkagia-metaxy-anagias-kai-klhroy---katekapse-15-ektario ; https://balla.com.cy/2026/09/ypo-elegcho-i-pyrkagia-metaxy-anagias-kai-klirou/ | W2: Κύπρος. Άγρια βλάστηση και διάσπαρτα πευκοδάση (~1,5 ha). Αιτία υπό διερεύνηση. | ~1,5 εκτάρια άγριας βλάστησης και διάσπαρτα πευκοδάση· Πυροσβεστική + Τμήμα Δασών + Υπηρεσία Θήρας & Πανίδας + εθελοντές SupportCy και Atlas | Επαρχία Λευκωσίας (Κύπρος). Οχήματα: 3 Πυρ.Υπηρεσία + 5 Τμ.Δασών + 1 Υπ.Θήρας και Πανίδας. Χωρίς εναέρια μέσα. | X2: 2026-09-23
A3: 46285 | E3: Κάτω Αρόδων – Κρίτου Τέρα | F3: Επαρχία Πάφου, Κύπρος | H3: Κρίτου Τέρα / Κάτω Αρόδες | P3: 0.4 | S3: υπό έλεγχο | T3: υπό διερεύνηση | V3: https://dialogos.com.cy/fotia-konta-se-kato-arodes-kai-kritoy-tera-diereynontai-ta-aitia/ | W3: ~4.000 τ.μ. (4 δεκάρια) ξηρού γρασιδιού· Πυροσβεστική Υπηρεσία + Τμήμα Δασών + Κ.Μ.Π. Κύπρου· αίτια υπό διερεύνηση με Αστυνομία | X3: 2026-09-23
A4: 46285 | E4: Κάτω Αρόδων – Κρίτου Τέρα | F4: Επαρχία Πάφου, Κύπρος | G4: Επαρχία Πάφου | H4: Κρίτου Τέρα / Κάτω Αρόδες | J4: 5 | P4: 4 | S4: κατασβέστηκε | T4: υπό διερεύνηση | V4: https://dialogos.com.cy/fotia-konta-se-kato-arodes-kai-kritoy-tera-diereynontai-ta-aitia/ ; https://www.sigmalive.com/news/local/1330132/ypo-eleghkho-pirkaghia-poy-ksespase-stis-arodes ; https://cyprustimes.com/astynomiko-reportaz/prolavan-kai-katesvisan-pyrkagia-stin-pafo-prin-parei-diastaseis/ ; https://www.politis.com.cy/politis-news/cyprus/1034306/neos-sinaghermos-stin-pafo-pirkaghia-ksespase-stis-arodes-speudoyn-dinameis-pirosvesis-vinteo ; https://www.alphanews.live/cyprus/vinteo-prolavan-ta-cheirotera-stin-pafo-sto-mikroskopio-pyrosvestikis-ki-astynomias-ta-aitia-tis-fotias/ | W4: Συμμετείχαν: 1 στελεχωμένο όχημα Πυροσβεστικής Υπηρεσίας + 2 στελεχωμένα οχήματα Τμήματος Δασών + 2 Κινητές Μονάδες Πυρόσβεσης (Κ.Μ.Π.). Πυρκαγιά σε ξηρά χόρτα. Κατασβέστηκε πριν πάρει διαστάσεις. Αρχική τιμή 0.4 ha πιθανώς λανθασμένη — πηγές αναφέρουν ~40 στρέμματα = 4 ha. | X4: 2026-09-23
A5: 46272 | E5: Αντάλεια (Ακσού-Κεπέζ-Δοσεμεαλτί-Σερίκ) | F5: Αντάλεια, Τουρκία | I5: 866 | J5: 181 | K5: 5 | L5: 10 | N5: 149 δεξαμενές νερού, 7 οχήματα TOMA, 25 βαρέα μηχανήματα | P5: 132 | S5: σε εξέλιξη | V5: https://www.turkiyetoday.com/nation/strong-winds-fan-antalya-fires-damaging-homes-and-farms-3227668 ; https://www.washingtontimes.com/news/2026/sep/8/wind-fueled-wildfire-forcing-hundreds-homes-turkey-firefighters/ | W5: 2η ημέρα στις 8/9. Ισχυροί άνεμοι. 5 σπίτια ακατοίκητα, ζημιές θερμοκηπίων/αγροτικών. Εκκένωση 3 γειτονιών + καταφύγιο ζώων Ακσού. 3 άτομα από εισπνοή καπνού. | Τουρκία — γεωγρ. Ευρώπη. Ισχυροί άνεμοι δυσχέραναν κατάσβεση. 5 σπίτια ακατοίκητα, ζημιές θερμοκήπια/γεωργία. 3 γειτονιές + καταφύγιο ζώων Ακσού εκκενώθηκαν. 3 άτομα εισπνοή καπνού. 149 δεξαμενές νερού, 7 TOMA, 25 βαρέα μηχ. Δεύτερη ημέρα 08/09 (email 1a081b75960a7438, 09:19 EEST). Καμένη έκταση ~132 ha (web). | X5: 2026-09-23
A6: 46256 | E6: Deliblato Sands (Άμμοι Δελιβλάτου) | F6: Σερβία — Δήμος Μπέλα Τσέρκβα | H6: Μπέλα Τσέρκβα | I6: 124 | J6: 39 | K6: 1 | L6: 4 | M6: Γερμανία + Ρουμανία (επίγειες ομάδες) | P6: 3500 | S6: οριοθετήθηκε | T6: καύσωνας / παρατεταμένη ξηρασία (θερμοκρασίες ~40°C) | V6: https://europeanwesternbalkans.com/2026/08/25/eu-firefighters-helped-battle-the-wildfires-in-deliblato-sands-over-the-weekend/ ; https://www.aljazeera.com/news/2026/8/24/eu-russian-aircraft-help-serbia-battle-wildfires ; https://balk.hu/2026/08/23/deliblato-sands-wildfire/ ; https://www.srbija.gov.rs/vest/en/284803/three-fire-hotspots-remain-active-in-deliblato-sands.php ; https://vreme.com/en/drustvo/deliblatska-pescara-pozar-vatrogasci/ | W6: Πρώτη ανίχνευση 21 Ιουλίου 2026· Μηχανισμός Πολιτικής Προστασίας ΕΕ ενεργοποιήθηκε 22-25/08· 4 ελικόπτερα Ρουμανία/Τσεχία/Σλοβακία + 124 επίγειο προσωπικό Γερμανία/Ρουμανία· ΦΔΠ Δελιβλάτου (Natura 2000) | Πυρκαγιά εκδηλώθηκε αρχικά 21/07/2026, επανέφλεξε πολλές φορές λόγω ισχυρών ανέμων. Ενεργοποίηση Μηχανισμού Πολιτικής Προστασίας ΕΕ (21/08/2026). Γερμανία: 55 πυροσβέστες + 24 οχήματα, Ρουμανία: 69 πυροσβέστες + 15 οχήματα = 124 σύνολο / 39 οχήματα. 4 ελικόπτερα Black Hawk (rescEU: ×1 Ρουμανία, ×2 Τσεχία, ×1 Σλοβακία). Ρωσικό IL-76 (42t χωρητικότητα νερού, aircraft=1). >3.500 ha ως 25/08 (αθροιστικά από 21/07 πιθανώς 9.000+ ha κατά balk.hu). | X6: 2026-08-30
A7: 46256 | E7: Σερβία (πολλαπλές εστίες) | F7: Σερβία | I7: 400 | K7: 1 | L7: 4 | P7: 3500 | S7: σε εξέλιξη | T7: Ακραία ξηρασία και καύσωνας | V7: https://www.aljazeera.com/news/2026/8/24/eu-russian-aircraft-help-serbia-battle-wildfires ; https://civil-protection-humanitarian-aid.ec.europa.eu/news-stories/news/eu-sends-urgent-support-serbia-wildfires-intensify-2026-08-24_en ; https://mapping.emergency.copernicus.eu/news/wildfire-in-serbia-emsr914/ | W7: Μηχανισμός Πολιτικής Προστασίας ΕΕ ανέπτυξε αεροσκάφη και πυροσβέστες. Ευρωπαϊκά και ρωσικά αεροσκάφη. Ενεργό 22–25 Αυγ 2026. Στατιστικά ΕΕ (25/8/2026): 1.780 συνολικές πυρκαγιές, 462 στην Ιταλία. | ΕΕ Μηχανισμός Πολιτικής Προστασίας ανέπτυξε αεροσκάφη και πυροσβέστες 22–25 Αυγ. Ρωσικά αεροσκάφη επίσης συνέδραμαν. | Ο Μηχανισμός Πολιτικής Προστασίας ΕΕ ανέπτυξε αεροσκάφη και πυροσβέστες 22–25 Αυγ 2026. Συνδρομή και ρωσικών αεροσκαφών. Στατιστικά ΕΕ (25/8): 1.780 πυρκαγιές συνολικά, 462 στην Ιταλία. | Κύριες εστίες: Deliblatska Pescara (>3.500 ha τεκμηριωμένα, Deliblato μόνο) και Stolovi (ΝΔ Σερβία). Ενεργοποίηση μηχανισμού πολιτικής προστασίας ΕΕ 21/8. ΕΕ: 4 Black Hawk ελικόπτερα (Ρουμανία/Σλοβακία/Τσεχία). Ρωσία: 1 Ilyushin Il-76 (168 τόνοι νερού σε μία ημέρα). Χερσαίες ομάδες από Γερμανία και Ρουμανία. Οι 400+ άνθρωποι αφορούν Deliblatska Pescara. | X7: 2026-08-27
A8: 46255 | E8: Deliblato Sands (Δελίβλατο) | F8: Vojvodina, Σερβία (Δήμος Μπέλα Τσέρκβα) | H8: Bela Crkva | I8: 124 | L8: 4 | M8: Γερμανία, Ρουμανία (124 επίγειο προσωπικό) | S8: σε εξέλιξη | V8: https://europeanwesternbalkans.com/2026/08/25/eu-firefighters-helped-battle-the-wildfires-in-deliblato-sands-over-the-weekend/ ; https://www.aljazeera.com/news/2026/8/24/eu-russian-aircraft-help-serbia-battle-wildfires | W8: Πρώτη ανίχνευση 21 Ιουλίου 2026. Ενεργοποίηση Μηχανισμού Πολιτικής Προστασίας ΕΕ με 4 ελικόπτερα (Ρουμανία, Τσεχία, Σλοβακία) + 124 πεζοί πυροσβέστες. Αναφορά ΕΕ 25 Αυγ. 2026. | X8: 2026-08-28
